<?xml version="1.0" ?>
<robot xmlns:xacro="http://ros.org/wiki/xacro">
	<xacro:macro name="motoman_mh5" params="prefix">

		<!-- link list -->
		<link name="world"/>  		<!-- ADDED NEW: World Link. Required for robot to be rigidly attached to world.-->

		<link name="${prefix}base_link">
			<visual>
			        <origin rpy="0 0 3.14159"/>
				<geometry>
					<mesh filename="package://motoman_mh5_support/meshes/mh5/visual/MH5_BASE_AXIS.stl" />
				</geometry>
				<material name="blue">
					<color rgba="0 0 1 1"/>
				</material>

			</visual>
			<collision>
			        <origin rpy="0 0 3.14159"/>
				<geometry>
					<mesh filename="package://motoman_mh5_support/meshes/mh5/collision/MH5_BASE_AXIS.stl" />
				</geometry>
				<material name="yellow">
					<color rgba="0 1 1 1"/>
				</material>
			</collision>
			<inertial>
	      <origin xyz="0 0 0.1" rpy="0 0 0"/>
	      <mass value="1"/>
	      <inertia
	        ixx="0.0077" ixy="0.0" ixz="0.0"
	        iyy="0.0066" iyz="0.0"
	        izz="0.0077"/>
	    </inertial>
		</link>

		<link name="${prefix}link_s">
			<visual>
				<geometry>
					<mesh filename="package://motoman_mh5_support/meshes/mh5/visual/MH5_S_AXIS.stl"/>
				</geometry>
				<material name="silver">
					<color rgba="0.8 0.8 0.8 1"/>
				</material>
			</visual>
			<collision>
				<geometry>
					<mesh filename="package://motoman_mh5_support/meshes/mh5/collision/MH5_S_AXIS.stl" />
				</geometry>
				<material name="yellow"/>
			</collision>
			<inertial>
	      <origin xyz="0 0 0.05" rpy="0 0 0"/>
	      <mass value="1"/>
	      <inertia
	        ixx="0.0052" ixy="0.0" ixz="0.0"
	        iyy="0.0052" iyz="0.0"
	        izz="0.0066"/>
	    </inertial>
		</link>
		<link name="${prefix}link_l">
			<visual>
				<!-- <origin rpy="1.57 3.1416 0" xyz="0 0 0"/> -->
				<geometry>
					<mesh filename="package://motoman_mh5_support/meshes/mh5/visual/MH5_L_AXIS.stl"/>
				</geometry>
				<material name="blue"/>
			</visual>
			<collision>
				<!-- <origin rpy="1.57 3.1416 0" xyz="0 0 0"/> -->
				<geometry>
					<mesh filename="package://motoman_mh5_support/meshes/mh5/collision/MH5_L_AXIS.stl" />
				</geometry>
				<material name="yellow"/>
			</collision>
			<inertial>
	      <origin xyz="0 0 0.13" rpy="0 0 0"/>
	      <mass value="1"/>
	      <inertia
	        ixx="0.02055" ixy="0.0" ixz="0.0"
	        iyy="0.01875" iyz="0.0"
	        izz="0.00555"/>
	    </inertial>
		</link>

		<link name="${prefix}link_u">
			<visual>
				<!-- <origin rpy="1.57 -3.1415 0" xyz="0 0 0"/> -->
				<geometry>
					<mesh filename="package://motoman_mh5_support/meshes/mh5/visual/MH5_U_AXIS.stl"/>
				</geometry>
				<material name="blue"/>
			</visual>
			<collision>
				<!-- <origin rpy="1.57 -3.1415 0" xyz="0 0 0"/> -->
				<geometry>
					<mesh filename="package://motoman_mh5_support/meshes/mh5/collision/MH5_U_AXIS.stl" />
				</geometry>
				<material name="yellow"/>
			</collision>
			<inertial>
	      <origin xyz="0 0 0.05" rpy="0 0 0"/>
	      <mass value="1"/>
	      <inertia
	        ixx="0.00328" ixy="0.0" ixz="0.0"
	        iyy="0.00354" iyz="0.0"
	        izz="0.00401"/>
	    </inertial>
		</link>

		<link name="${prefix}link_r">
			<visual>
				<!-- <origin rpy="0 0 3.1416" xyz="0 0 0"/> -->
				<geometry>
					<mesh filename="package://motoman_mh5_support/meshes/mh5/visual/MH5_R_AXIS.stl"/>
				</geometry>
				<material name="silver"/>
			</visual>
			<collision>
				<!-- <origin rpy="0 0 3.1416" xyz="0 0 0"/> -->
				<geometry>
					<mesh filename="package://motoman_mh5_support/meshes/mh5/collision/MH5_R_AXIS.stl" />
				</geometry>
				<material name="yellow"/>
			</collision>
			<inertial>
	      <origin xyz="0.1 0 0" rpy="0 0 0"/>
	      <mass value="1"/>
	      <inertia
	        ixx="0.00184" ixy="0.0" ixz="0.0"
	        iyy="0.00708" iyz="0.0"
	        izz="0.00691"/>
	    </inertial>
		</link>

		<link name="${prefix}link_b">
			<visual>
				<!-- <origin rpy="-1.57 0 3.1416" xyz="0 0 0"/> -->
				<geometry>
					<mesh filename="package://motoman_mh5_support/meshes/mh5/visual/MH5_B_AXIS.stl"/>
				</geometry>
				<material name="blue"/>
			</visual>
			<collision>
				<!-- <origin rpy="-1.57 0 3.1416" xyz="0 0 0"/> -->
				<geometry>
					<mesh filename="package://motoman_mh5_support/meshes/mh5/collision/MH5_B_AXIS.stl" />
				</geometry>
				<material name="yellow"/>
			</collision>
			<inertial>
	      <origin xyz="0.05 0 0" rpy="0 0 0"/>
	      <mass value="1"/>
	      <inertia
	        ixx="0.000708" ixy="0.0" ixz="0.0"
	        iyy="0.001308" iyz="0.0"
	        izz="0.004167"/>
	    </inertial>
		</link>

		<link name="${prefix}link_t">
			<visual>
				<geometry>
					<mesh filename="package://motoman_mh5_support/meshes/mh5/visual/MH5_T_AXIS.stl" />
				</geometry>
				<material name="silver"/>
			</visual>
			<collision>
				<geometry>
					<mesh filename="package://motoman_mh5_support/meshes/mh5/collision/MH5_T_AXIS.stl" />
				</geometry>
				<material name="yellow"/>
			</collision>
			<inertial>
	      <origin xyz="0 0 0" rpy="0 0 0"/>
	      <mass value="1"/>
	      <inertia
	        ixx="0.00041667" ixy="0.0" ixz="0.0"
	        iyy="0.00028333" iyz="0.0"
	        izz="0.00028333"/>
	    </inertial>
		</link>
		<!-- end of link list -->

		<!-- joint list -->
		<joint name="fixed" type="fixed">  <!-- ADDED BY ADAM:: Start -->
			<parent link="world"/>
			<child link="${prefix}base_link"/>
		</joint>               		         <!-- ADDED BY ADAM:: END -->

		<joint name="${prefix}joint_s" type="revolute">
			<parent link="${prefix}base_link"/>
			<child link="${prefix}link_s"/>
			<origin xyz="0 0 0.1990" rpy="0 0 0"/>
			<axis xyz="0 0 1" />
			<limit lower="-2.9671" upper="2.9671" effort="100" velocity="2.96" />
		</joint>
		<joint name="${prefix}joint_l" type="revolute">
			<parent link="${prefix}link_s"/>
			<child link="${prefix}link_l"/>
			<origin xyz="0.0880 0 0.1310" rpy="0 0 0"/>
			<axis xyz="0 1 0" />
			<limit lower="-1.1345" upper="2.6180" effort="100" velocity="2.96" />
		</joint>
		<joint name="${prefix}joint_u" type="revolute">
			<parent link="${prefix}link_l"/>
			<child link="${prefix}link_u"/>
			<origin xyz="0 0 0.3100" rpy="0 0 0"/>
			<axis xyz="0 -1 0" />
      <!-- Old limits: lower="-2.3736" upper="4.4506" The new limits
           below were measured from an MH5F.  They ensure that link_r
           won't hit link_l even when joint_r is at 45 degrees.  The
           old limits were converted directly from the MH5 data sheet,
           which was clearly way off.
				  .. Noted by ACBUYNAK February 2020 -->
			<limit lower="-1.0122" upper="3.2218" effort="100" velocity="2.96" />
		</joint>
		<joint name="${prefix}joint_r" type="revolute">
			<parent link="${prefix}link_u"/>
			<child link="${prefix}link_r"/>
			<origin xyz="0.0715 0 0.0399" rpy="0 0 0"/>
			<axis xyz="-1 0 0" />
			<limit lower="-3.3161" upper="3.3161" effort="100" velocity="3.48" />
		</joint>
		<joint name="${prefix}joint_b" type="revolute">
			<parent link="${prefix}link_r"/>
			<child link="${prefix}link_b"/>
			<origin xyz="0.2335 0 0" rpy="0 0 0"/>
			<axis xyz="0 -1 0" />
			<limit lower="-2.1817" upper="2.1817" effort="100" velocity="3.48" />
		</joint>
		<joint name="${prefix}joint_t" type="revolute">
			<parent link="${prefix}link_b"/>
			<child link="${prefix}link_t"/>
			<origin xyz="0.0865 0 0" rpy="0 0 0"/>
			<axis xyz="-1 0 0" />
			<limit lower="-6.2831" upper="6.2831" effort="100" velocity="6.97" />
		</joint>
		<!-- end of joint list -->
	</xacro:macro>

</robot>
