<?xml version="1.0" encoding="utf-8"?>
<!-- This URDF was automatically created by SolidWorks to URDF Exporter! Originally created by Stephen Brawner (brawner@gmail.com)
     Commit Version: 1.5.1-0-g916b5db  Build Version: 1.5.7152.31018
     For more information, please see http://wiki.ros.org/sw_urdf_exporter -->
<robot
  name="ms210">
  <link  name="base_link">
    <inertial>
      <origin
        xyz="-0.0969353333485605 0.00019476061508981 0.148802927004027"
        rpy="0 0 0" />
      <mass
        value="85.3734144789457" />
      <inertia
        ixx="2.07062891397542"
        ixy="0.000411796913095095"
        ixz="-0.169557337897038"
        iyy="4.01531369457381"
        iyz="0.00101729194004793"
        izz="4.69087622403026" />
    </inertial>
    <visual>
      <origin
        xyz="0 0 0"
        rpy="0 0 0" />
      <geometry>
        <mesh
          filename="package://motoman_ms210_support/meshes/base_link.STL" />
      </geometry>
      <material
        name="">
        <color
          rgba="0 0.4 0.4 1" />
      </material>
    </visual>
    <collision>
      <origin
        xyz="0 0 0"
        rpy="0 0 0" />
      <geometry>
        <mesh
          filename="package://motoman_ms210_support/meshes/base_link.STL" />
      </geometry>
    </collision>
  </link>
  <link  name="link_s">
    <inertial>
      <origin
        xyz="0.1084002986612 0.0517026136587477 0.232398536276916"
        rpy="0 0 0" />
      <mass
        value="51.5240795117508" />
      <inertia
        ixx="1.83931840430019"
        ixy="-0.459402138194338"
        ixz="-0.395129802076457"
        iyy="3.26551008534587"
        iyz="-0.366514032620982"
        izz="3.26563055113986" />
    </inertial>
    <visual>
      <origin
        xyz="0 0 0"
        rpy="0 0 0" />
      <geometry>
        <mesh
          filename="package://motoman_ms210_support/meshes/link_s.STL" />
      </geometry>
      <material
        name="">
        <color
          rgba="0 0.4 0.4 1" />
      </material>
    </visual>
    <collision>
      <origin
        xyz="0 0 0"
        rpy="0 0 0" />
      <geometry>
        <mesh
          filename="package://motoman_ms210_support/meshes/link_s.STL" />
      </geometry>
    </collision>
  </link>
  <joint name="joint_s"
    type="continuous">
    <origin
      xyz="0 -0.262 0"
      rpy="1.5708 -0.021404 0" />
    <parent
      link="base_link" />
    <child
      link="link_s" />
    <axis
      xyz="0 0 1" />
    <limit
      lower="-3.1416"
      upper="3.1416"
      effort="0"
      velocity="0" />
  </joint>
  <link  name="link_l">
    <inertial>
      <origin
        xyz="0.321255117167952 -0.028368905789887 1.09499881709944"
        rpy="0 0 0" />
      <mass
        value="62.236048662205" />
      <inertia
        ixx="8.15494076066324"
        ixy="0.0029258782875198"
        ixz="0.0575270520969251"
        iyy="8.26747463532137"
        iyz="0.405728947181277"
        izz="0.622051249903859" />
    </inertial>
    <visual>
      <origin
        xyz="0 0 0"
        rpy="0 0 0" />
      <geometry>
        <mesh
          filename="package://motoman_ms210_support/meshes/link_l.STL" />
      </geometry>
      <material
        name="">
        <color
          rgba="0 0.4 0.4 1" />
      </material>
    </visual>
    <collision>
      <origin
        xyz="0 0 0"
        rpy="0 0 0" />
      <geometry>
        <mesh
          filename="package://motoman_ms210_support/meshes/link_l.STL" />
      </geometry>
    </collision>
  </link>
  <joint name="joint_l"
    type="continuous">
    <origin
      xyz="0.015747 0 -0.26964"
      rpy="0 -0.024083 0" />
    <parent
      link="link_s" />
    <child
      link="link_l" />
    <axis
      xyz="0 0 0" />
    <limit
      lower="-1.0472"
      upper="1.3265"
      effort="0"
      velocity="0" />
  </joint>
  <link  name="link_u">
    <inertial>
      <origin
        xyz="0.261475479305764 0.0397544664639943 0.184913318693553"
        rpy="0 0 0" />
      <mass
        value="61.9521236780792" />
      <inertia
        ixx="1.98880500386994"
        ixy="0.435245443167339"
        ixz="-1.63578982571973"
        iyy="7.42942470768916"
        iyz="0.375495507861086"
        izz="6.54756328759177" />
    </inertial>
    <visual>
      <origin
        xyz="0 0 0"
        rpy="0 0 0" />
      <geometry>
        <mesh
          filename="package://motoman_ms210_support/meshes/link_u.STL" />
      </geometry>
      <material
        name="">
        <color
          rgba="0 0.4 0.4 1" />
      </material>
    </visual>
    <collision>
      <origin
        xyz="0 0 0"
        rpy="0 0 0" />
      <geometry>
        <mesh
          filename="package://motoman_ms210_support/meshes/link_u.STL" />
      </geometry>
    </collision>
  </link>
  <joint name="joint_u"
    type="continuous">
    <origin
      xyz="0.325 -0.00021402 1.8"
      rpy="0 0.46111 0" />
    <parent
      link="link_l" />
    <child
      link="link_u" />
    <axis
      xyz="0 1 0" />
    <limit
      lower="-2.5656"
      upper="1.5708"
      effort="0"
      velocity="0" />
  </joint>
  <link  name="link_r">
    <inertial>
      <origin
        xyz="0.146105819710883 -0.0559583268574394 3.98935784247101E-05"
        rpy="0 0 0" />
      <mass
        value="6.48881754880285" />
      <inertia
        ixx="0.0362651868934917"
        ixy="0.015303145986784"
        ixz="-8.38097047526666E-06"
        iyy="0.0561439242615243"
        iyz="-2.47013171349387E-05"
        izz="0.0667540959508842" />
    </inertial>
    <visual>
      <origin
        xyz="0 0 0"
        rpy="0 0 0" />
      <geometry>
        <mesh
          filename="package://motoman_ms210_support/meshes/link_r.STL" />
      </geometry>
      <material
        name="">
        <color
          rgba="0 0.4 0.4 1" />
      </material>
    </visual>
    <collision>
      <origin
        xyz="0 0 0"
        rpy="0 0 0" />
      <geometry>
        <mesh
          filename="package://motoman_ms210_support/meshes/link_r.STL" />
      </geometry>
    </collision>
  </link>
  <joint name="joint_r"
    type="continuous">
    <origin
      xyz="1.0365 0.00021402 0.3"
      rpy="0.0094618 0 0" />
    <parent
      link="link_u" />
    <child
      link="link_r" />
    <axis
      xyz="1 0 0" />
    <limit
      lower="-6.2832"
      upper="6.2832"
      effort="0"
      velocity="0" />
  </joint>
  <link  name="link_b">
    <inertial>
      <origin
        xyz="0.0920586065412201 -0.013255489806254 6.32486081293404E-05"
        rpy="0 0 0" />
      <mass
        value="5.83918565889158" />
      <inertia
        ixx="0.0401869297760405"
        ixy="0.0046206280655018"
        ixz="-1.47997952329969E-05"
        iyy="0.0531105727168547"
        iyz="9.81420612570741E-05"
        izz="0.0631395503155317" />
    </inertial>
    <visual>
      <origin
        xyz="0 0 0"
        rpy="0 0 0" />
      <geometry>
        <mesh
          filename="package://motoman_ms210_support/meshes/link_b.STL" />
      </geometry>
      <material
        name="">
        <color
          rgba="0 0.4 0.4 1" />
      </material>
    </visual>
    <collision>
      <origin
        xyz="0 0 0"
        rpy="0 0 0" />
      <geometry>
        <mesh
          filename="package://motoman_ms210_support/meshes/link_b.STL" />
      </geometry>
    </collision>
  </link>
  <joint name="joint_b"
    type="continuous">
    <origin
      xyz="0.18851 0 0"
      rpy="0 -0.18526 0" />
    <parent
      link="link_r" />
    <child
      link="link_b" />
    <axis
      xyz="0 1 0" />
    <limit
      lower="-2.2689"
      upper="2.2689"
      effort="0"
      velocity="0" />
  </joint>
  <link  name="link_t">
    <inertial>
      <origin
        xyz="0.0217192175747298 4.9591121182857E-05 -2.65145729258891E-05"
        rpy="0 0 0" />
      <mass
        value="0.571660195914766" />
      <inertia
        ixx="0.00261266388392397"
        ixy="-7.08533470690671E-07"
        ixz="1.18895787439185E-07"
        iyy="0.00133440954914045"
        iyz="-1.21394809791374E-06"
        izz="0.00133467235878143" />
    </inertial>
    <visual>
      <origin
        xyz="0 0 0"
        rpy="0 0 0" />
      <geometry>
        <mesh
          filename="package://motoman_ms210_support/meshes/link_t.STL" />
      </geometry>
      <material
        name="">
        <color
          rgba="0 0.4 0.4 1" />
      </material>
    </visual>
    <collision>
      <origin
        xyz="0 0 0"
        rpy="0 0 0" />
      <geometry>
        <mesh
          filename="package://motoman_ms210_support/meshes/link_t.STL" />
      </geometry>
    </collision>
  </link>
  <joint name="joint_t"
    type="continuous">
    <origin
      xyz="0.21566 0 0"
      rpy="-1.5749 0 0" />
    <parent
      link="link_b" />
    <child
      link="link_t" />
    <axis
      xyz="1 0 0" />
    <limit
      lower="-6.2832"
      upper="6.2832"
      effort="0"
      velocity="0" />
  </joint>
</robot>
